Workbook

Sheet 종합
A1: 프로젝트 사전 VRB | J1: 고객예산vs투찰금액 | M1: vat별도
A2: 발주처 | B2: 육군본부 | D2: 사업명 | F2: 23~25년 상용정보통신장비 통합유지보수 | J2: (%) | K2: 투찰금액 | M2: (%) | N2: 투찰금액
A3: 수주형태 | D3: ① 매출금액 | F3: 5214923748 | J3: 1 | K3: 5853485840 | M3: 1 | N3: =K3/1.1 -> 5.3213508e+09
A4: 사업기간 | B4: 23.01 ~ 24.12 | E4: ⒜용역 | F4: =F3-F5 -> 469343138 | J4: 1 | K4: =K$3*J4 -> 5853485840 | M4: 1 | N4: =$N$3*M4 -> 5.3213508e+09
A5: 총투입MM | B5: ='2.자체 및 외주 투입인력'!D33 -> 48 | C5: MM | E5: ⒝제품 | F5: ='1.상품&솔루션&용역'!G50 -> 4745580610 | G5: ⒞기타 | J5: 0.99 | K5: =K$3*J5 -> 5.794951e+09 | M5: 0.99 | N5: =$N$3*M5 -> 5.2681373e+09
A6: 작성자/PM | C6: 작성일 | D6: 2023.05.22 | F6: Contin%(SI 10%, SM 2%) | H6: 0.02 | J6: 0.98 | K6: =K$3*J6 -> 5.7364161e+09 | M6: 0.98 | N6: =$N$3*M6 -> 5.2149237e+09
H7: (단위:원) | J7: 0.97 | K7: =K$3*J7 -> 5.6778813e+09 | M7: 0.97 | N7: =$N$3*M7 -> 5.1617102e+09
A8: 구분 | C8: 산출근거 | F8: 원가 | J8: 0.96 | K8: =K$3*J8 -> 5.6193464e+09 | M8: 0.96 | N8: =$N$3*M8 -> 5.1084967e+09
A9: ② 상품 & 솔루션 | C9: - | F9: =+'1.상품&솔루션&용역'!G50 -> 4745580610 | J9: 0.95 | K9: =K$3*J9 -> 5560811548 | M9: 0.95 | N9: =$N$3*M9 -> 5.0552832e+09
A10: ③ 인건비 | C10: =SUM(C11:D13) -> 48 | E10: MM | F10: =SUM(F11:H13) -> 401402400 | J10: 0.94 | K10: =K$3*J10 -> 5.5022767e+09 | M10: 0.94 | N10: =$N$3*M10 -> 5.0020697e+09
B11: ⓐ 정규인력 | C11: =+'2.자체 및 외주 투입인력'!D12 -> 48 | E11: MM | F11: ='2.자체 및 외주 투입인력'!F12 -> 401402400 | J11: 0.93 | K11: =K$3*J11 -> 5.4437418e+09 | M11: 0.93 | N11: =$N$3*M11 -> 4.9488562e+09
B12: ⓑ 외주비(업체) | C12: ='2.자체 및 외주 투입인력'!D25 -> 0 | E12: MM | F12: =+'2.자체 및 외주 투입인력'!F25 -> 0 | J12: 0.92 | K12: =K$3*J12 -> 5.385207e+09 | M12: 0.92 | N12: =$N$3*M12 -> 4.8956427e+09
B13: ⓒ 외주비(프리랜서) | C13: =+'2.자체 및 외주 투입인력'!D31 -> 0 | E13: MM | F13: ='2.자체 및 외주 투입인력'!F31 -> 0 | J13: 0.9 | K13: =K$3*J13 -> 5268137256 | M13: 0.9 | N13: =$N$3*M13 -> 4.7892157e+09
A14: ④ 직접경비 | C14: 외주 및 내부경비 합계 | F14: =SUM(F15:H16) -> 1.0062711e+08 | J14: 0.88 | K14: =K$3*J14 -> 5.1510675e+09 | M14: 0.88 | N14: =$N$3*M14 -> 4.6827887e+09
B15: ⓓ 내부경비 | C15: - | F15: ='3.내부경비'!F28:H28 -> 1.0062711e+08 | J15: 0.86 | K15: =K$3*J15 -> 5.0339978e+09 | M15: 0.86 | N15: =$N$3*M15 -> 4.5763617e+09
B16: ⓔ 외주경비 | C16: - | J16: 0.85 | K16: =K$3*J16 -> 4975462964 | M16: 0.85 | N16: =$N$3*M16 -> 4.5231481e+09
A17: ⑤ 직접비 합계 | C17: ②+③+④ | F17: =+F9+F10+F14 -> 5.2476101e+09 | J17: 0.84 | K17: =K$3*J17 -> 4.9169281e+09 | M17: 0.84 | N17: =$N$3*M17 -> 4.4699346e+09
A18: ⑥ Contingency | C18: 외주인건비 및 직접경비의 컨틴전시 | F18: =F19+F20 -> 2012542.2 | J18: 0.83 | K18: =K$3*J18 -> 4.8583932e+09 | M18: 0.83 | N18: =$N$3*M18 -> 4.4167211e+09
B19: ⓕ 외주인건비 | C19: (ⓑ+ⓒ)×Contin.% | F19: =(F12+F13)*H6 -> 0 | J19: 0.82 | K19: =K$3*J19 -> 4.7998584e+09 | M19: 0.82 | N19: =$N$3*M19 -> 4.3635076e+09
B20: ⓖ 직접경비 | C20: ④×Contin.% | F20: =F14*H6 -> 2012542.2 | J20: 0.81 | K20: =K$3*J20 -> 4.7413235e+09 | M20: 0.81 | N20: =$N$3*M20 -> 4.3102941e+09
A21: ⑦ GP1(정규인건비 포함) | C21: ①-⑤-⑥+ⓐ | F21: =F3-F17-F18+F11 -> 3.6670349e+08 | J21: 0.8 | K21: =K$3*J21 -> 4682788672 | M21: 0.8 | N21: =$N$3*M21 -> 4.2570806e+09
B22: ⓗ 매출총이익률 | C22: ⑦÷① | F22: =F21/F3 -> 0.070318092 | J22: 0.78 | K22: =K$3*J22 -> 4.565719e+09 | M22: 0.78 | N22: =$N$3*M22 -> 4.1506536e+09
A23: ⑧ GP2(정규인건비 공제) | C23: ⑦-ⓐ | F23: =F21-F11 -> -34698912 | J23: 0.77 | K23: =K$3*J23 -> 4.5071841e+09 | M23: 0.77 | N23: =$N$3*M23 -> 4.0974401e+09
B24: ⓘ 공헌이익율 | C24: ⑧÷① | F24: =F23/F3 -> -0.0066537717 | J24: 0.76 | K24: =K$3*J24 -> 4.4486492e+09 | M24: 0.76 | N24: =$N$3*M24 -> 4.0442266e+09
A25: ⑨ 간접비 | F25: =SUM(F26:H29) -> 2.5756742e+08 | J25: 0.75 | K25: =K$3*J25 -> 4390114380 | M25: 0.75 | N25: =$N$3*M25 -> 3.9910131e+09
B26: ⓙ 정규 | C26: ='5.인건비및간접비테이블'!C13 -> 2400000 | E26: ='2.자체 및 외주 투입인력'!D12 -> 48 | F26: =C26*E26 -> 115200000 | J26: 0.74 | K26: =K$3*J26 -> 4.3315795e+09 | M26: 0.74 | N26: =$N$3*M26 -> 3.9377996e+09
B27: ⓚ 외주 | C27: =+'5.인건비및간접비테이블'!C14 -> 960000 | E27: ='2.자체 및 외주 투입인력'!D25 -> 0 | F27: =C27*E27 -> 0 | J27: 0.73 | K27: =K$3*J27 -> 4.2730447e+09 | M27: 0.73 | N27: =$N$3*M27 -> 3.8845861e+09
B28: ⓛ 제품...⒝기준 | C28: =+F5 -> 4745580610 | E28: 0.03 | F28: =C28*E28 -> 1.4236742e+08 | J28: 0.72 | K28: =K$3*J28 -> 4.2145098e+09 | M28: 0.72 | N28: =$N$3*M28 -> 3.8313725e+09
B29: ⓛ 기타...⒞기준 | C29: =+H5 -> 0 | E29: 0.06 | F29: =C29*E29 -> 0 | J29: 0.71 | K29: =K$3*J29 -> 4.1559749e+09 | M29: 0.71 | N29: =$N$3*M29 -> 3.778159e+09
A30: ⑩ 세전순이익 | C30: ⑧-⑨ | F30: =F23-F25 -> -2.9226633e+08 | J30: 0.7 | K30: =K$3*J30 -> 4.0974401e+09 | M30: 0.7 | N30: =$N$3*M30 -> 3.7249455e+09
B31: ⓜ 순이익률 | C31: ⑩÷① | F31: =F30/F3 -> -0.056044219
F32: 2020 목표 이익율 | H32: 0.085
F33: S | G33: 12% 이상 | H33: B이상 사업이 전체 매출액의60% 이상 시 목표 달성
F34: A | G34: 10% 이상
F35: B | G35: 8% 이상
F36: C | G36: 5% 이상
F37: D | G37: 5% 미만
A38: ※ 입찰가격 평점 산식(공공부문)
A39: ① 입찰가격이 추정가격의 80% 이상
A40: 평점 = 입찰가격평가 배점한도 * (최저입찰가격 / 당해입찰가격)
...

Sheet 1.상품&솔루션&용역
G1: (단위:원)
A2: 구분 | B2: 내역 | C2: 산정기준 | E2: 수량 | F2: 적용단가 | G2: 금액 | H2: 업체명 | I2: 담당자 | J2: 연락처 | K2: e-mail | L2: 비고
A3: H/W
B8: 소계 | E8: =SUM(E3:E7) -> 0 | G8: =SUM(G3:G7) -> 0
A9: S/W | B9: 넷백업, Veritas CFS | E9: 2 | H9: 파인브이티
B10: ESA 종합분석시스템 | E10: 2 | H10: 에스지에이솔루션즈(ESA)
B11: PatchChaser V2.1 (PMS) | E11: 2 | H11: 에스지에이솔루션즈(PMS)
B12: APPM 2000 (업무망 서버 패스워드 관리) | E12: 2 | H12: 굿모닝아이텍
B13: Magic SSO / EAM (2 EA) | E13: 2 | H13: 드림시큐리티
B14: Touchen transkey (PC 키패드보안, 모바일 키패드보안) | E14: 2 | H14: 라온시큐어
B15: 대량메일 발송 (아이메일러) | E15: 2 | H15: 모비젠
B16: 보안USB관리시스템 | E16: 2 | H16: 하이엔드솔루션(비젯)
B17: ks-PMIS (PMIS 자료이관) | E17: 2 | H17: 상아매니지먼트컨설팅
B18: Jennifer | E18: 2 | H18: 싸이웰시스템
B19: IPSCAN XE | E19: 2 | H19: 스콥정보통신
B20: D'Amo (DB암호화 솔루션) | E20: 2 | H20: 열림데이타시스템
B21: 통합검색(Search Formula-1 5.3) | E21: 2 | H21: 와이즈넛
... B28: PRIMERGY RX1330 M2 (한싹자료전송시스템) | E28: 2 | H28: 한싹
B48: 데이터스트림즈(QualityStream) | E48: 2 | G48: 4745580610
B49: 소계 | E49: =SUM(E9:E48) -> 42 | G49: =SUM(G9:G48) -> 4745580610
A50: 합계 | E50: =E8+E49 -> 42 | G50: =G8+G49 -> 4745580610

Sheet 2.자체 및 외주 투입인력
A1: ※ 같은 직급이 다수 인원일 경우, 복사후 '복사한 셀 삽입' 이용
A2: ◆ 자체투입인력
A3: 역할 | B3: 이름 | C3: 직급 | D3: M/M | E3: - | F3: 원가합계 | G3: M1 | H3: M2 | I3: M3 | J3: M4 | K3: M5 | L3: M6 | M3: M7 | N3: M8 | O3: M9 | P3: M10 | Q3: M11 | R3: M12 | S3: M13 | T3: M14 | U3: M15 | V3: M16 | W3: M17 | X3: M18 | Y3: M19 | Z3: M20 | AA3: M21 | AB3: M22 | AC3: M23 | AD3: M24
A4: PM | C4: 이사 | D4: 24 | E4: =VLOOKUP(C4,'[1]5.인건비및간접비테이블'!$B$3:$D$8,2,FALSE) -> 10129700 | F4: =D4*E4 -> 243112800 | G4: 1 | H4: 1 | I4: 1 | J4: 1 | K4: 1 | L4: 1 | M4: 1 | N4: 1 | O4: 1 | P4: 1 | Q4: 1 | R4: 1 | S4: 1 | T4: 1 | U4: 1 | V4: 1 | W4: 1 | X4: 1 | Y4: 1 | Z4: 1 | AA4: 1 | AB4: 1 | AC4: 1 | AD4: 1
A5: 사업관리 | B5: TBD | C5: 과장 | D5: 24 | E5: 6595400 | F5: =E5*D5 -> 158289600 | G5: 1 | H5: 1 | I5: 1 | J5: 1 | K5: 1 | L5: 1 | M5: 1 | N5: 1 | O5: 1 | P5: 1 | Q5: 1 | R5: 1 | S5: 1 | T5: 1 | U5: 1 | V5: 1 | W5: 1 | X5: 1 | Y5: 1 | Z5: 1 | AA5: 1 | AB5: 1 | AC5: 1 | AD5: 1
A12: 합계 | D12: =SUM(D4:D11) -> 48 | F12: =SUM(F4:F11) -> 401402400 | G12: =SUM(G4:G11) -> 2 | H12: =SUM(H4:H11) -> 2 | I12: =SUM(I4:I11) -> 2 | J12: =SUM(J4:J11) -> 2 | K12: =SUM(K4:K11) -> 2 | L12: =SUM(L4:L11) -> 2 | M12: =SUM(M4:M11) -> 2 | ... T12: =SUM(T4:T11) -> 2
A14: ◆ 외주투입인력
A15: 협력업체명 | B15: 이름 | C15: 등급(직위) | D15: M/M | E15: 적용단가 | F15: 금액 | G15: M1 | H15: M2 | I15: M3 | J15: M4 | K15: M5 | L15: M6 | M15: M7 | N15: M8 | O15: M9 | P15: M10 | Q15: M11 | R15: M12 | S15: M13 | T15: M14 | U15: M15 | V15: M16 | W15: M17 | X15: M18 | Y15: M19 | Z15: M20 | AA15: M21 | AB15: M22 | AC15: M23 | AD15: M24
D23: =SUM(G23:M23) -> 0
D24: =SUM(D16:D23) -> 0 | F24: =SUM(F16:F22) -> 0 | G24: =SUM(G16:G16) -> 0 | H24: =SUM(H16:H16) -> 0 | I24: =SUM(I16:I16) -> 0 | J24: =SUM(J16:J16) -> 0 | K24: =SUM(K16:K16) -> 0 | L24: =SUM(L16:L16) -> 0 | M24: =SUM(M16:M16) -> 0 | N24: =SUM(N16:N16) -> 0 | ... T24: =SUM(T16:T16) -> 0
A25: 합계 | D25: =SUM(D24) -> 0 | F25: =SUM(F24) -> 0 | G25: =SUM(G24) -> 0 | H25: =SUM(H24) -> 0 | I25: =SUM(I24) -> 0 | J25: =SUM(J24) -> 0 | K25: =SUM(K24) -> 0 | L25: =SUM(L24) -> 0 | M25: =SUM(M24) -> 0 | ... T25: =SUM(T24) -> 0
A26: 프리랜서 | B26: 이름 | C26: 등급(직위) | D26: M/M | E26: 적용단가 | F26: 금액 | G26: M2 | H26: M3 | I26: M4 | J26: M5 | K26: M6 | L26: M7 | M26: M7 | N26: M8 | O26: M9 | P26: M10 | Q26: M11 | R26: M12 | S26: M13 | T26: M14
D27: =SUM(G27:L27) -> 0 | F27: =E27*D27 -> 0
D28: =SUM(G28:L28) -> 0 | F28: =E28*D28 -> 0
D29: =SUM(G29:L29) -> 0 | F29: =E29*D29 -> 0
D30: =SUM(G30:L30) -> 0 | F30: =E30*D30 -> 0
C31: 소계 | D31: =SUM(D27:D30) -> 0 | F31: =SUM(F27:F30) -> 0 | G31: =SUM(G27:G30) -> 0 | H31: =SUM(H27:H30) -> 0 | I31: =SUM(I27:I30) -> 0 | J31: =SUM(J27:J30) -> 0 | K31: =SUM(K27:K30) -> 0 | L31: =SUM(L27:L30) -> 0 | M31: =SUM(M27:M30) -> 0 | ... T31: =SUM(T27:T30) -> 0
A32: 합계 | D32: =D31 -> 0 | F32: =+F31 -> 0 | G32: =G31 -> 0 | H32: =H31 -> 0 | I32: =I31 -> 0 | J32: =J31 -> 0 | K32: =K31 -> 0 | L32: =L31 -> 0 | M32: =M31 -> 0 | N32: =N31 -> 0 | ... T32: =T31 -> 0
C33: 총합계 | D33: =D12+D25+D32 -> 48 | F33: =F12+F25+F32 -> 401402400

Sheet 3.내부경비
A1: 프로젝트 원가 산정(경비)
A2: PJT CODE | C2: 사업명 | E2: =종합!F2 -> 23~25년 상용정보통신장비 통합유지보수 | J2: (참고1)PJ관리비 기준
A3: 사업기간 | B3: =종합!B4 -> 23.01 ~ 24.12 | C3: 고객예산 | D3: 용역+상품 | E3: =+종합!F3 -> 5214923748 | J3: 직원 1MM | K3: SI | L3: 20만원
A4: 총MM | B4: ='2.자체 및 외주 투입인력'!D12 -> 48 | D4: 상품 | E4: =종합!F5 -> 4745580610 | J4: 직원 2MM | K4: SM | L4: 10만원
A5: 작성자 | B5: =종합!B6 -> 0 | C5: 작성일 | E5: 2023-05-22
J6: (참고2)사업관리비 기준
H7: (단위:원) | J7: 매출 | K7: 한도 | L7: 비고
A8: 구분 | B8: 내역 | C8: 산정기준 | E8: 수량 | F8: 적용단가 | H8: 금액 | J8: 2억이상 | K8: 0.004
A9: 수행 | B9: PJ관리비(야근식대,회의비,회식비,소모품비) | C9: 20만원/인당(식대한도 8천원/인당, 회식비 15,000/인당) | E9: =B4 -> 48 | F9: 200000 | H9: =F9*E9 -> 9600000 | J9: 2억미만 | K9: 800000
B10: 사업관리비(킥오프,중간보고,종료보고) | C10: 2억이하 80만, 이상0.4% | E10: 1 | F10: =E3*0.4% -> 20859695 | H10: =F10*E10 -> 20859695
B11: 출장교통비(영업 및 수행) | C11: 6만원/인(왕복기준) | E11: 0 | H11: =E11*F11 -> 0 | J11: (참고3)대외 PJ수당 기준
B12: 출장숙박비(영업 및 수행) | C12: 6만원/인(1박기준) | E12: 0 | H12: =F12*E12 -> 0 | J12: SI Project | L12: 30만원
B13: 출장여비(식대,회의비) | C13: 3만원/인(실비) | E13: 0 | H13: =F13*E13 -> 0 | J13: SM Project | L13: 20만원
B14: 지방파견수당(수행) | C14: 120만원/인 (부산 140만원) | H14: =F14*E14 -> 0
B15: 프로젝트 수당(수행) | C15: SI : 30만원, SM : 20만원 | H15: =F15*E15 -> 0 | J15: (참고4) 예산 내역
B16: 외주비(제안 지원,디자인) | C16: 제안 시 지원인력 용역비 | F16: 15000000 | H16: 15000000 | J16: PJ 수행 시 예상되는 모든 예산 작성
B17: 도서인쇄비 | C17: PJ 관련 산출물 제본비 | E17: 1 | F17: 1000000 | H17: =F17*E17 -> 1000000 | J17: 작성 외 예산 사용은 변경 VRB 작성 후 지출
B18: 사전영업비(회의비,교통비,출장비 등) | C18: 수주를 위한 모든 영업활동비(0.4%) | E18: 1 | F18: =E3*0.4% -> 20859695 | H18: =F18 -> 20859695 | J18: (참고4) 예산 초과 시
B19: 렌탈료 / 지급수수료 | C19: 데스크탑, 노트북, 모니터, 프린터, 가구 등 렌탈 시 | E19: 0 | H19: =F19*E19 -> 0 | J19: (참고5) 예산 초과 시
B20: 소모품 | C20: 커피, 종이컵 외 비품 구입 | E20: 0 | F20: 0 | J20: 별도의 특별 승인을 받고 진행
B21: 통신비 | C21: PJ관련 네트워크 설치 및 통신비 | E21: 0 | F21: 0
B22: 공통비 | E22: 0 | F22: 0
B23: 계약이행보증보험 | C23: 0.1 | D23: 0.01 | E23: 1 | F23: =E3*C23*D23 -> 5214923.7 | H23: =F23*E23 -> 5214923.7 | J23: 개시일 | K23: 종료일 | L23: 일수
B24: 선급금이행보증 | C24: 0.3 | D24: 0.019 | E24: 1 | F24: =E4*C24*D24 -> 27049809 | H24: =F24*E24 -> 27049809 | J24: 2022 | K24: 44562 | L24: 180 | M24: >선금/계약
B25: 하자이행보증보험 | C25: 0.05 | D25: 0.004 | E25: 1 | F25: =E3*C25*D25 -> 1042984.7 | H25: =F25 -> 1042984.7 | L25: =K25-J25 -> 0 | M25: >하자
B26: 임대료
B27: 기타
A28: 합계 | F28: =SUM(H9:H27) -> 1.0062711e+08

Sheet 5.인건비및간접비테이블
A1: 인건비테이블 | C1: 2022년
A3: 2021 정규직 인건비 | B3: 상무 이상 | C3: 12429800 | F3: 11118000
B4: 이사 | C4: 10129700 | F4: 9027000
B5: 부장 | C5: 9680900 | F5: 8619000
B6: 차장 | C6: 8390600 | F6: 7446000
B7: 과장 | C7: 6595400 | F7: 5814000
B8: 대리/주임 | C8: 5641700 | F8: 4970000
A9: 인건비 = 2020년 급여+4대보험회사부담분+퇴직연금+학자금
A11: 2020년 간접비 원가 배분 테이블
A13: 정규인력 간접비 할당 | C13: 2400000 | D13: >투입MM 당
A14: 외주인력 간접비 할당 | C14: 960000 | D14: >투입MM 당
A15: 제품매출 간접비 할당 | C15: 0.2 | D15: >판매금액 기준
A16: 기타매출 간접비 할당 | C16: 0.04 | D16: >판매금액 기준
A17: 간접비 = 2019년 공통비+영업외비용
C22: 제약사항
